Workbook

Sheet INPUT | WORKFORCE
B2: Role Category | C2: Role Description | D2: Group | E2: FTE
B3: GP and PCN | C3: Digital and Transformation Lead | D3: NA | E3: 11
B4: GP and PCN | C4: Managers | D4: NA | E4: 112
B5: GP and PCN | C5: Apprentices | D5: NA | E5: 20.4
B6: GP and PCN | C6: Digital and Transformation Lead | D6: NA | E6: 0
B7: GP and PCN | C7: Estates and Ancillary | D7: NA | E7: 5.1
B8: GP and PCN | C8: Management Partners | D8: NA | E8: 4
B9: GP and PCN | C9: Medical Secretaries | D9: NA | E9: 75.7
B10: GP and PCN | C10: Other Admin and Non-Clinical | D10: NA | E10: 293.1
B11: GP and PCN | C11: Telephonists | D11: NA | E11: 2.4
B12: GP and PCN | C12: Receptionists | D12: NA | E12: 447.5
B13: GP and PCN | C13: Non-clinical Director | D13: NA | E13: 0
B14: GP and PCN | C14: GP Partners | D14: F | E14: 175
... B117: Social Care | C117: Other Social Care | D117: NA | E117: 1700

Sheet INPUT | POPULATION
B2: Year | C2: Count of Conditions | D2: Number of Patients
B3: 2022 | C3: 0 | D3: 110926
B4: 2022 | C4: 1 | D4: 164439
B5: 2022 | C5: 2 | D5: 131776
B6: 2022 | C6: 3 | D6: 83070
B7: 2022 | C7: 4 | D7: 48210
B8: 2022 | C8: 5 | D8: 27570
B9: 2022 | C9: 6 | D9: 14439
B10: 2022 | C10: 7 | D10: 6791
B11: 2022 | C11: 8 | D11: 2880
B12: 2022 | C12: 9 | D12: 1110
B13: 2022 | C13: 10 | D13: 339
B14: 2022 | C14: 11 | D14: 97
... B381: 2047 | C381: 14 | D381: 3

Sheet INPUT | SEGMENTATION
B2: Period | C2: Year
B3: Baseline | C3: 2025
B4: Forecast | C4: 2045
C6: Conditions | E6: Population | G6: % of Popn
B7: Segment Description | C7: From (>=) | D7: To (<) | E7: Baseline | F7: Forecast | G7: Baseline | H7: Forecast | I7: % Growth
B8: Green | C8: 0 | D8: 2 | E8: =SUMIFS('INPUT | POPULATION'!$D:$D,'INPUT | POPULATION'!$B:$B,$C$3,'INPUT | POPULATION'!$C:$C,">="&$C8,'INPUT | POPULATION'!$C:$C,"<"&$D8) -> 276957 | F8: =SUMIFS('INPUT | POPULATION'!$D:$D,'INPUT | POPULATION'!$B:$B,$C$4,'INPUT | POPULATION'!$C:$C,">="&$C8,'INPUT | POPULATION'!$C:$C,"<"&$D8) -> 283417 | G8: =E8/E$12 -> 0.45686643 | H8: =F8/F$12 -> 0.42362819 | I8: =(F8-E8)/E8 -> 0.02332492
B9: Amber | C9: 2 | D9: 6 | E9: =SUMIFS('INPUT | POPULATION'!$D:$D,'INPUT | POPULATION'!$B:$B,$C$3,'INPUT | POPULATION'!$C:$C,">="&$C9,'INPUT | POPULATION'!$C:$C,"<"&$D9) -> 301734 | F9: =SUMIFS('INPUT | POPULATION'!$D:$D,'INPUT | POPULATION'!$B:$B,$C$4,'INPUT | POPULATION'!$C:$C,">="&$C9,'INPUT | POPULATION'!$C:$C,"<"&$D9) -> 346014 | G9: =E9/E$12 -> 0.49773841 | H9: =F9/F$12 -> 0.51719298 | I9: =(F9-E9)/E9 -> 0.14675177
B10: Blue | C10: 6 | D10: 8 | E10: =SUMIFS('INPUT | POPULATION'!$D:$D,'INPUT | POPULATION'!$B:$B,$C$3,'INPUT | POPULATION'!$C:$C,">="&$C10,'INPUT | POPULATION'!$C:$C,"<"&$D10) -> 22669 | F10: =SUMIFS('INPUT | POPULATION'!$D:$D,'INPUT | POPULATION'!$B:$B,$C$4,'INPUT | POPULATION'!$C:$C,">="&$C10,'INPUT | POPULATION'!$C:$C,"<"&$D10) -> 32227 | G10: =E10/E$12 -> 0.037394632 | H10: =F10/F$12 -> 0.048170242 | I10: =(F10-E10)/E10 -> 0.42163307
B11: Red | C11: 8 | D11: 16 | E11: =SUMIFS('INPUT | POPULATION'!$D:$D,'INPUT | POPULATION'!$B:$B,$C$3,'INPUT | POPULATION'!$C:$C,">="&$C11,'INPUT | POPULATION'!$C:$C,"<"&$D11) -> 4850 | F11: =SUMIFS('INPUT | POPULATION'!$D:$D,'INPUT | POPULATION'!$B:$B,$C$4,'INPUT | POPULATION'!$C:$C,">="&$C11,'INPUT | POPULATION'!$C:$C,"<"&$D11) -> 7365 | G11: =E11/E$12 -> 0.0080005279 | H11: =F11/F$12 -> 0.01100859 | I11: =(F11-E11)/E11 -> 0.5185567
E12: =SUM(E8:E11) -> 606210 | F12: =SUM(F8:F11) -> 669023 | I12: =(F12-E12)/E12 -> 0.10361591

Sheet CALC | TASK STD
B2: Original Horizon 2035 Matrix | K2: Workforce Group Standardised Revised Horizon 2035 Matrix
C4: Skill Level | L4: Group
B5: Task | C5: 1 | D5: 2 | E5: 3 | F5: 4 | G5: 5 | H5: 6 | I5: Overall | K5: Task | L5: A | M5: B | N5: C | O5: D | P5: E | Q5: F | R5: Overall
B6: Prevent | C6: 0.1745 | D6: 0.0402 | E6: 0.019 | F6: 0.0048 | G6: 0.002 | H6: 0.0007 | I6: 0.2412 | K6: Prevention, Enablement and Rehabilitation | L6: =C20/C$24 -> 0.49821337 | M6: =D20/D$24 -> 0.38022814 | N6: =E20/E$24 -> 0.33148019 | O6: =F20/F$24 -> 0.3368984 | P6: =G20/G$24 -> 0.2327044 | Q6: =H20/H$24 -> 0.27083333 | R6: =I20/I$24 -> 0.43805619
B7: Enable | C7: 0.0881 | D7: 0.0267 | E7: 0.0179 | F7: 0.0041 | G7: 0.0011 | H7: 0.0003 | I7: 0.1382 | K7: Assessment and Planning | L7: =C21/C$24 -> 0.19908116 | M7: =D21/D$24 -> 0.24429658 | N7: =E21/E$24 -> 0.3161918 | O7: =F21/F$24 -> 0.27807487 | P7: =G21/G$24 -> 0.36477987 | Q7: =H21/H$24 -> 0.375 | R7: =I21/I$24 -> 0.23187681
B8: Assess | C8: 0.0587 | D8: 0.0338 | E8: 0.0258 | F8: 0.0061 | G8: 0.004 | H8: 0.0011 | I8: 0.1295 | K8: Treatment and Relieving | L8: =C22/C$24 -> 0.24842607 | M8: =D22/D$24 -> 0.22338403 | N8: =E22/E$24 -> 0.17164698 | O8: =F22/F$24 -> 0.15240642 | P8: =G22/G$24 -> 0.19496855 | Q8: =H22/H$24 -> 0.1875 | R8: =I22/I$24 -> 0.22737726
B9: Plan | C9: 0.0583 | D9: 0.0176 | E9: 0.0197 | F9: 0.0043 | G9: 0.0018 | H9: 0.0007 | I9: 0.1024 | K9: Linking | L9: =C23/C$24 -> 0.054279394 | M9: =D23/D$24 -> 0.15209125 | N9: =E23/E$24 -> 0.18068103 | O9: =F23/F$24 -> 0.23262032 | P9: =G23/G$24 -> 0.20754717 | Q9: =H23/H$24 -> 0.16666667 | R9: =I23/I$24 -> 0.10268973
B10: Treat | C10: 0 | D10: 0.0059 | E10: 0.0071 | F10: 0.003 | G10: 0.0019 | H10: 0.0006 | I10: 0.0185 | K10: Overall | L10: =SUM(L6:L9) -> 1 | M10: =SUM(M6:M9) -> 1 | N10: =SUM(N6:N9) -> 1 | O10: =SUM(O6:O9) -> 1 | P10: =SUM(P6:P9) -> 1 | Q10: =SUM(Q6:Q9) -> 1 | R10: =SUM(R6:R9) -> 1
B11: Rehabilitate | C11: 0.0302 | D11: 0.0131 | E11: 0.0108 | F11: 0.0037 | G11: 0.0006 | H11: 0.0003 | I11: 0.0587
B12: Relieve | C12: 0.146 | D12: 0.0411 | E12: 0.0176 | F12: 0.0027 | G12: 0.0012 | H12: 0.0003 | I12: 0.2089
B13: Link | C13: 0.0319 | D13: 0.032 | E13: 0.026 | F13: 0.0087 | G13: 0.0033 | H13: 0.0008 | I13: 0.1027
B14: Overall | C14: 0.5877 | D14: 0.2104 | E14: 0.1439 | F14: 0.0374 | G14: 0.0159 | H14: 0.0048 | I14: 1.0001
B16: Revised Horizon 2035 Matrix
C18: Skill Level
B19: Task | C19: 1 | D19: 2 | E19: 3 | F19: 4 | G19: 5 | H19: 6 | I19: Overall
B20: Prevention, Enablement and Rehabilitation | C20: =C6+C7+C11 -> 0.2928 | D20: =D6+D7+D11 -> 0.08 | E20: =E6+E7+E11 -> 0.0477 | F20: =F6+F7+F11 -> 0.0126 | G20: =G6+G7+G11 -> 0.0037 | H20: =H6+H7+H11 -> 0.0013 | I20: =SUM(C20:H20) -> 0.4381
B21: Assessment and Planning | C21: =C8+C9 -> 0.117 | D21: =D8+D9 -> 0.0514 | E21: =E8+E9 -> 0.0455 | F21: =F8+F9 -> 0.0104 | G21: =G8+G9 -> 0.0058 | H21: =H8+H9 -> 0.0018 | I21: =SUM(C21:H21) -> 0.2319
B22: Treatment and Relieving | C22: =C10+C12 -> 0.146 | D22: =D10+D12 -> 0.047 | E22: =E10+E12 -> 0.0247 | F22: =F10+F12 -> 0.0057 | G22: =G10+G12 -> 0.0031 | H22: =H10+H12 -> 0.0009 | I22: =SUM(C22:H22) -> 0.2274
B23: Linking | C23: =C13 -> 0.0319 | D23: =D13 -> 0.032 | E23: =E13 -> 0.026 | F23: =F13 -> 0.0087 | G23: =G13 -> 0.0033 | H23: =H13 -> 0.0008 | I23: =SUM(C23:H23) -> 0.1027
B24: Overall | C24: =SUM(C20:C23) -> 0.5877 | D24: =SUM(D20:D23) -> 0.2104 | E24: =SUM(E20:E23) -> 0.1439 | F24: =SUM(F20:F23) -> 0.0374 | G24: =SUM(G20:G23) -> 0.0159 | H24: =SUM(H20:H23) -> 0.0048 | I24: =SUM(I20:I23) -> 1.0001

Sheet INPUT | BLINE | TASKS
B2: Green Segment | K2: Amber Segment | T2: Workforce Group Standardised - Revised Horizon 2035 Matrix
C4: Workforce Group | L4: Workforce Group | U4: Skill Level
B5: Task | C5: A | D5: B | E5: C | F5: D | G5: E | H5: F | I5: Overall | K5: Task | L5: A | M5: B | N5: C | O5: D | P5: E | Q5: F | R5: Overall | T5: Task | U5: A | V5: B | W5: C | X5: D | Y5: E | Z5: F | AA5: Overall
B6: Prevention, Enablement and Rehabilitation | C6: =U6 -> 0.49821337 | D6: =V6 -> 0.38022814 | E6: =W6 -> 0.33148019 | F6: =X6 -> 0.3368984 | G6: =Y6 -> 0.2327044 | H6: =Z6 -> 0.27083333 | I6: =AA6 -> 0.43805619 | K6: Prevention, Enablement and Rehabilitation | L6: =U6 -> 0.49821337 | M6: =V6 -> 0.38022814 | N6: =W6 -> 0.33148019 | O6: =X6 -> 0.3368984 | P6: =Y6 -> 0.2327044 | Q6: =Z6 -> 0.27083333 | R6: =AA6 -> 0.43805619 | T6: Prevention, Enablement and Rehabilitation | U6: ='CALC | TASK STD'!L6 -> 0.49821337 | V6: ='CALC | TASK STD'!M6 -> 0.38022814 | W6: ='CALC | TASK STD'!N6 -> 0.33148019 | X6: ='CALC | TASK STD'!O6 -> 0.3368984 | Y6: ='CALC | TASK STD'!P6 -> 0.2327044 | Z6: ='CALC | TASK STD'!Q6 -> 0.27083333 | AA6: ='CALC | TASK STD'!R6 -> 0.43805619
B7: Assessment and Planning | C7: =U7 -> 0.19908116 | D7: =V7 -> 0.24429658 | E7: =W7 -> 0.3161918 | F7: =X7 -> 0.27807487 | G7: =Y7 -> 0.36477987 | H7: =Z7 -> 0.375 | I7: =AA7 -> 0.23187681 | K7: Assessment and Planning | L7: =U7 -> 0.19908116 | M7: =V7 -> 0.24429658 | N7: =W7 -> 0.3161918 | O7: =X7 -> 0.27807487 | P7: =Y7 -> 0.36477987 | Q7: =Z7 -> 0.375 | R7: =AA7 -> 0.23187681 | T7: Assessment and Planning | U7: ='CALC | TASK STD'!L7 -> 0.19908116 | V7: ='CALC | TASK STD'!M7 -> 0.24429658 | W7: ='CALC | TASK STD'!N7 -> 0.3161918 | X7: ='CALC | TASK STD'!O7 -> 0.27807487 | Y7: ='CALC | TASK STD'!P7 -> 0.36477987 | Z7: ='CALC | TASK STD'!Q7 -> 0.375 | AA7: ='CALC | TASK STD'!R7 -> 0.23187681
B8: Treatment and Relieving | C8: =U8 -> 0.24842607 | D8: =V8 -> 0.22338403 | E8: =W8 -> 0.17164698 | F8: =X8 -> 0.15240642 | G8: =Y8 -> 0.19496855 | H8: =Z8 -> 0.1875 | I8: =AA8 -> 0.22737726 | K8: Treatment and Relieving | L8: =U8 -> 0.24842607 | M8: =V8 -> 0.22338403 | N8: =W8 -> 0.17164698 | O8: =X8 -> 0.15240642 | P8: =Y8 -> 0.19496855 | Q8: =Z8 -> 0.1875 | R8: =AA8 -> 0.22737726 | T8: Treatment and Relieving | U8: ='CALC | TASK STD'!L8 -> 0.24842607 | V8: ='CALC | TASK STD'!M8 -> 0.22338403 | W8: ='CALC | TASK STD'!N8 -> 0.17164698 | X8: ='CALC | TASK STD'!O8 -> 0.15240642 | Y8: ='CALC | TASK STD'!P8 -> 0.19496855 | Z8: ='CALC | TASK STD'!Q8 -> 0.1875 | AA8: ='CALC | TASK STD'!R8 -> 0.22737726
B9: Linking | C9: =U9 -> 0.054279394 | D9: =V9 -> 0.15209125 | E9: =W9 -> 0.18068103 | F9: =X9 -> 0.23262032 | G9: =Y9 -> 0.20754717 | H9: =Z9 -> 0.16666667 | I9: =AA9 -> 0.10268973 | K9: Linking | L9: =U9 -> 0.054279394 | M9: =V9 -> 0.15209125 | N9: =W9 -> 0.18068103 | O9: =X9 -> 0.23262032 | P9: =Y9 -> 0.20754717 | Q9: =Z9 -> 0.16666667 | R9: =AA9 -> 0.10268973 | T9: Linking | U9: ='CALC | TASK STD'!L9 -> 0.054279394 | V9: ='CALC | TASK STD'!M9 -> 0.15209125 | W9: ='CALC | TASK STD'!N9 -> 0.18068103 | X9: ='CALC | TASK STD'!O9 -> 0.23262032 | Y9: ='CALC | TASK STD'!P9 -> 0.20754717 | Z9: ='CALC | TASK STD'!Q9 -> 0.16666667 | AA9: ='CALC | TASK STD'!R9 -> 0.10268973
B10: Overall | C10: =SUM(C6:C9) -> 1 | D10: =SUM(D6:D9) -> 1 | E10: =SUM(E6:E9) -> 1 | F10: =SUM(F6:F9) -> 1 | G10: =SUM(G6:G9) -> 1 | H10: =SUM(H6:H9) -> 1 | I10: =SUM(I6:I9) -> 1 | K10: Overall | L10: =SUM(L6:L9) -> 1 | M10: =SUM(M6:M9) -> 1 | N10: =SUM(N6:N9) -> 1 | O10: =SUM(O6:O9) -> 1 | P10: =SUM(P6:P9) -> 1 | Q10: =SUM(Q6:Q9) -> 1 | R10: =SUM(R6:R9) -> 1 | T10: Overall | U10: =SUM(U6:U9) -> 1 | V10: =SUM(V6:V9) -> 1 | W10: =SUM(W6:W9) -> 1 | X10: =SUM(X6:X9) -> 1 | Y10: =SUM(Y6:Y9) -> 1 | Z10: =SUM(Z6:Z9) -> 1 | AA10: =SUM(AA6:AA9) -> 1
B12: Blue Segment | K12: Red Segment
C14: Workforce Group | L14: Workforce Group
B15: Task | C15: A | D15: B | E15: C | F15: D | G15: E | H15: F | I15: Overall | K15: Task | L15: A | M15: B | N15: C | O15: D | P15: E | Q15: F | R15: Overall
B16: Prevention, Enablement and Rehabilitation | C16: =U6 -> 0.49821337 | D16: =V6 -> 0.38022814 | E16: =W6 -> 0.33148019 | F16: =X6 -> 0.3368984 | G16: =Y6 -> 0.2327044 | H16: =Z6 -> 0.27083333 | I16: =AA6 -> 0.43805619 | K16: Prevention, Enablement and Rehabilitation | L16: =U6 -> 0.49821337 | M16: =V6 -> 0.38022814 | N16: =W6 -> 0.33148019 | O16: =X6 -> 0.3368984 | P16: =Y6 -> 0.2327044 | Q16: =Z6 -> 0.27083333 | R16: =AA6 -> 0.43805619
B17: Assessment and Planning | C17: =U7 -> 0.19908116 | D17: =V7 -> 0.24429658 | E17: =W7 -> 0.3161918 | F17: =X7 -> 0.27807487 | G17: =Y7 -> 0.36477987 | H17: =Z7 -> 0.375 | I17: =AA7 -> 0.23187681 | K17: Assessment and Planning | L17: =U7 -> 0.19908116 | M17: =V7 -> 0.24429658 | N17: =W7 -> 0.3161918 | O17: =X7 -> 0.27807487 | P17: =Y7 -> 0.36477987 | Q17: =Z7 -> 0.375 | R17: =AA7 -> 0.23187681
B18: Treatment and Relieving | C18: =U8 -> 0.24842607 | D18: =V8 -> 0.22338403 | E18: =W8 -> 0.17164698 | F18: =X8 -> 0.15240642 | G18: =Y8 -> 0.19496855 | H18: =Z8 -> 0.1875 | I18: =AA8 -> 0.22737726 | K18: Treatment and Relieving | L18: =U8 -> 0.24842607 | M18: =V8 -> 0.22338403 | N18: =W8 -> 0.17164698 | O18: =X8 -> 0.15240642 | P18: =Y8 -> 0.19496855 | Q18: =Z8 -> 0.1875 | R18: =AA8 -> 0.22737726
B19: Linking | C19: =U9 -> 0.054279394 | D19: =V9 -> 0.15209125 | E19: =W9 -> 0.18068103 | F19: =X9 -> 0.23262032 | G19: =Y9 -> 0.20754717 | H19: =Z9 -> 0.16666667 | I19: =AA9 -> 0.10268973 | K19: Linking | L19: =U9 -> 0.054279394 | M19: =V9 -> 0.15209125 | N19: =W9 -> 0.18068103 | O19: =X9 -> 0.23262032 | P19: =Y9 -> 0.20754717 | Q19: =Z9 -> 0.16666667 | R19: =AA9 -> 0.10268973
B20: Overall | C20: =SUM(C16:C19) -> 1 | D20: =SUM(D16:D19) -> 1 | E20: =SUM(E16:E19) -> 1 | F20: =SUM(F16:F19) -> 1 | G20: =SUM(G16:G19) -> 1 | H20: =SUM(H16:H19) -> 1 | I20: =SUM(I16:I19) -> 1 | K20: Overall | L20: =SUM(L16:L19) -> 1 | M20: =SUM(M16:M19) -> 1 | N20: =SUM(N16:N19) -> 1 | O20: =SUM(O16:O19) -> 1 | P20: =SUM(P16:P19) -> 1 | Q20: =SUM(Q16:Q19) -> 1 | R20: =SUM(R16:R19) -> 1
B24: Workforce Split by Group and Population Segment | K24: Workforce Hours per Year by Group
C26: Workforce Group | L26: Workforce Group
B27: Segment | C27: A | D27: B | E27: C | F27: D | G27: E | H27: F | K27: Segment | L27: A | M27: B | N27: C | O27: D | P27: E | Q27: F
B28: Green | C28: 0.25 | D28: 0.25 | E28: 0.25 | F28: 0.25 | G28: 0.25 | H28: 0.25 | K28: Weeks per FTE | L28: 44 | M28: 44 | N28: 44 | O28: 44 | P28: 44 | Q28: 44
B29: Amber | C29: 0.25 | D29: 0.25 | E29: 0.25 | F29: 0.25 | G29: 0.25 | H29: 0.25 | K29: Hours per Week | L29: 37.5 | M29: 37.5 | N29: 37.5 | O29: 37.5 | P29: 37.5 | Q29: 37.5
B30: Blue | C30: 0.25 | D30: 0.25 | E30: 0.25 | F30: 0.25 | G30: 0.25 | H30: 0.25 | K30: Overall | L30: =44*37.5 -> 1650 | M30: =44*37.5 -> 1650 | N30: =44*37.5 -> 1650 | O30: =44*37.5 -> 1650 | P30: =44*37.5 -> 1650 | Q30: =44*37.5 -> 1650
B31: Red | C31: 0.25 | D31: 0.25 | E31: 0.25 | F31: 0.25 | G31: 0.25 | H31: 0.25
B32: Overall | C32: =SUM(C28:C31) -> 1 | D32: =SUM(D28:D31) -> 1 | E32: =SUM(E28:E31) -> 1 | F32: =SUM(F28:F31) -> 1 | G32: =SUM(G28:G31) -> 1 | H32: =SUM(H28:H31) -> 1

Sheet INPUT | FCAST | TASKS
B2: Green Segment | K2: Amber Segment | T2: Workforce Group Standardised - Revised Horizon 2035 Matrix
C4: Workforce Group | L4: Workforce Group | U4: Skill Level
B5: Task | C5: A | D5: B | E5: C | F5: D | G5: E | H5: F | I5: Overall | K5: Task | L5: A | M5: B | N5: C | O5: D | P5: E | Q5: F | R5: Overall | T5: Task | U5: A | V5: B | W5: C | X5: D | Y5: E | Z5: F | AA5: Overall
B6: Prevention, Enablement and Rehabilitation | C6: =U6 -> 0.49821337 | D6: =V6 -> 0.38022814 | E6: =W6 -> 0.33148019 | F6: =X6 -> 0.3368984 | G6: =Y6 -> 0.2327044 | H6: =Z6 -> 0.27083333 | I6: =AA6 -> 0.43805619 | K6: Prevention, Enablement and Rehabilitation | L6: =U6 -> 0.49821337 | M6: =V6 -> 0.38022814 | N6: =W6 -> 0.33148019 | O6: =X6 -> 0.3368984 | P6: =Y6 -> 0.2327044 | Q6: =Z6 -> 0.27083333 | R6: =AA6 -> 0.43805619 | T6: Prevention, Enablement and Rehabilitation | U6: ='CALC | TASK STD'!L6 -> 0.49821337 | V6: ='CALC | TASK STD'!M6 -> 0.38022814 | W6: ='CALC | TASK STD'!N6 -> 0.33148019 | X6: ='CALC | TASK STD'!O6 -> 0.3368984 | Y6: ='CALC | TASK STD'!P6 -> 0.2327044 | Z6: ='CALC | TASK STD'!Q6 -> 0.27083333 | AA6: ='CALC | TASK STD'!R6 -> 0.43805619
B7: Assessment and Planning | C7: =U7 -> 0.19908116 | D7: =V7 -> 0.24429658 | E7: =W7 -> 0.3161918 | F7: =X7 -> 0.27807487 | G7: =Y7 -> 0.36477987 | H7: =Z7 -> 0.375 | I7: =AA7 -> 0.23187681 | K7: Assessment and Planning | L7: =U7 -> 0.19908116 | M7: =V7 -> 0.24429658 | N7: =W7 -> 0.3161918 | O7: =X7 -> 0.27807487 | P7: =Y7 -> 0.36477987 | Q7: =Z7 -> 0.375 | R7: =AA7 -> 0.23187681 | T7: Assessment and Planning | U7: ='CALC | TASK STD'!L7 -> 0.19908116 | V7: ='CALC | TASK STD'!M7 -> 0.24429658 | W7: ='CALC | TASK STD'!N7 -> 0.3161918 | X7: ='CALC | TASK STD'!O7 -> 0.27807487 | Y7: ='CALC | TASK STD'!P7 -> 0.36477987 | Z7: ='CALC | TASK STD'!Q7 -> 0.375 | AA7: ='CALC | TASK STD'!R7 -> 0.23187681
B8: Treatment and Relieving | C8: =U8 -> 0.24842607 | D8: =V8 -> 0.22338403 | E8: =W8 -> 0.17164698 | F8: =X8 -> 0.15240642 | G8: =Y8 -> 0.19496855 | H8: =Z8 -> 0.1875 | I8: =AA8 -> 0.22737726 | K8: Treatment and Relieving | L8: =U8 -> 0.24842607 | M8: =V8 -> 0.22338403 | N8: =W8 -> 0.17164698 | O8: =X8 -> 0.15240642 | P8: =Y8 -> 0.19496855 | Q8: =Z8 -> 0.1875 | R8: =AA8 -> 0.22737726 | T8: Treatment and Relieving | U8: ='CALC | TASK STD'!L8 -> 0.24842607 | V8: ='CALC | TASK STD'!M8 -> 0.22338403 | W8: ='CALC | TASK STD'!N8 -> 0.17164698 | X8: ='CALC | TASK STD'!O8 -> 0.15240642 | Y8: ='CALC | TASK STD'!P8 -> 0.19496855 | Z8: ='CALC | TASK STD'!Q8 -> 0.1875 | AA8: ='CALC | TASK STD'!R8 -> 0.22737726
B9: Linking | C9: =U9 -> 0.054279394 | D9: =V9 -> 0.15209125 | E9: =W9 -> 0.18068103 | F9: =X9 -> 0.23262032 | G9: =Y9 -> 0.20754717 | H9: =Z9 -> 0.16666667 | I9: =AA9 -> 0.10268973 | K9: Linking | L9: =U9 -> 0.054279394 | M9: =V9 -> 0.15209125 | N9: =W9 -> 0.18068103 | O9: =X9 -> 0.23262032 | P9: =Y9 -> 0.20754717 | Q9: =Z9 -> 0.16666667 | R9: =AA9 -> 0.10268973 | T9: Linking | U9: ='CALC | TASK STD'!L9 -> 0.054279394 | V9: ='CALC | TASK STD'!M9 -> 0.15209125 | W9: ='CALC | TASK STD'!N9 -> 0.18068103 | X9: ='CALC | TASK STD'!O9 -> 0.23262032 | Y9: ='CALC | TASK STD'!P9 -> 0.20754717 | Z9: ='CALC | TASK STD'!Q9 -> 0.16666667 | AA9: ='CALC | TASK STD'!R9 -> 0.10268973
B10: Overall | C10: =SUM(C6:C9) -> 1 | D10: =SUM(D6:D9) -> 1 | E10: =SUM(E6:E9) -> 1 | F10: =SUM(F6:F9) -> 1 | G10: =SUM(G6:G9) -> 1 | H10: =SUM(H6:H9) -> 1 | I10: =SUM(I6:I9) -> 1 | K10: Overall | L10: =SUM(L6:L9) -> 1 | M10: =SUM(M6:M9) -> 1 | N10: =SUM(N6:N9) -> 1 | O10: =SUM(O6:O9) -> 1 | P10: =SUM(P6:P9) -> 1 | Q10: =SUM(Q6:Q9) -> 1 | R10: =SUM(R6:R9) -> 1 | T10: Overall | U10: =SUM(U6:U9) -> 1 | V10: =SUM(V6:V9) -> 1 | W10: =SUM(W6:W9) -> 1 | X10: =SUM(X6:X9) -> 1 | Y10: =SUM(Y6:Y9) -> 1 | Z10: =SUM(Z6:Z9) -> 1 | AA10: =SUM(AA6:AA9) -> 1
B12: Blue Segment | K12: Red Segment
C14: Workforce Group | L14: Workforce Group
B15: Task | C15: A | D15: B | E15: C | F15: D | G15: E | H15: F | I15: Overall | K15: Task | L15: A | M15: B | N15: C | O15: D | P15: E | Q15: F | R15: Overall
B16: Prevention, Enablement and Rehabilitation | C16: =U6 -> 0.49821337 | D16: =V6 -> 0.38022814 | E16: =W6 -> 0.33148019 | F16: =X6 -> 0.3368984 | G16: =Y6 -> 0.2327044 | H16: =Z6 -> 0.27083333 | I16: =AA6 -> 0.43805619 | K16: Prevention, Enablement and Rehabilitation | L16: =U6 -> 0.49821337 | M16: =V6 -> 0.38022814 | N16: =W6 -> 0.33148019 | O16: =X6 -> 0.3368984 | P16: =Y6 -> 0.2327044 | Q16: =Z6 -> 0.27083333 | R16: =AA6 -> 0.43805619
B17: Assessment and Planning | C17: =U7 -> 0.19908116 | D17: =V7 -> 0.24429658 | E17: =W7 -> 0.3161918 | F17: =X7 -> 0.27807487 | G17: =Y7 -> 0.36477987 | H17: =Z7 -> 0.375 | I17: =AA7 -> 0.23187681 | K17: Assessment and Planning | L17: =U7 -> 0.19908116 | M17: =V7 -> 0.24429658 | N17: =W7 -> 0.3161918 | O17: =X7 -> 0.27807487 | P17: =Y7 -> 0.36477987 | Q17: =Z7 -> 0.375 | R17: =AA7 -> 0.23187681
B18: Treatment and Relieving | C18: =U8 -> 0.24842607 | D18: =V8 -> 0.22338403 | E18: =W8 -> 0.17164698 | F18: =X8 -> 0.15240642 | G18: =Y8 -> 0.19496855 | H18: =Z8 -> 0.1875 | I18: =AA8 -> 0.22737726 | K18: Treatment and Relieving | L18: =U8 -> 0.24842607 | M18: =V8 -> 0.22338403 | N18: =W8 -> 0.17164698 | O18: =X8 -> 0.15240642 | P18: =Y8 -> 0.19496855 | Q18: =Z8 -> 0.1875 | R18: =AA8 -> 0.22737726
B19: Linking | C19: =U9 -> 0.054279394 | D19: =V9 -> 0.15209125 | E19: =W9 -> 0.18068103 | F19: =X9 -> 0.23262032 | G19: =Y9 -> 0.20754717 | H19: =Z9 -> 0.16666667 | I19: =AA9 -> 0.10268973 | K19: Linking | L19: =U9 -> 0.054279394 | M19: =V9 -> 0.15209125 | N19: =W9 -> 0.18068103 | O19: =X9 -> 0.23262032 | P19: =Y9 -> 0.20754717 | Q19: =Z9 -> 0.16666667 | R19: =AA9 -> 0.10268973
B20: Overall | C20: =SUM(C16:C19) -> 1 | D20: =SUM(D16:D19) -> 1 | E20: =SUM(E16:E19) -> 1 | F20: =SUM(F16:F19) -> 1 | G20: =SUM(G16:G19) -> 1 | H20: =SUM(H16:H19) -> 1 | I20: =SUM(I16:I19) -> 1 | K20: Overall | L20: =SUM(L16:L19) -> 1 | M20: =SUM(M16:M19) -> 1 | N20: =SUM(N16:N19) -> 1 | O20: =SUM(O16:O19) -> 1 | P20: =SUM(P16:P19) -> 1 | Q20: =SUM(Q16:Q19) -> 1 | R20: =SUM(R16:R19) -> 1
B24: Workforce Split by Group and Population Segment | K24: Workforce Hours per Year by Group
C26: Workforce Group | L26: Workforce Group
B27: Segment | C27: A | D27: B | E27: C | F27: D | G27: E | H27: F | K27: Segment | L27: A | M27: B | N27: C | O27: D | P27: E | Q27: F
B28: Green | C28: 0.25 | D28: 0.25 | E28: 0.25 | F28: 0.25 | G28: 0.25 | H28: 0.25 | K28: Weeks per FTE | L28: 44 | M28: 44 | N28: 44 | O28: 44 | P28: 44 | Q28: 44
B29: Amber | C29: 0.25 | D29: 0.25 | E29: 0.25 | F29: 0.25 | G29: 0.25 | H29: 0.25 | K29: Hours per Week | L29: 37.5 | M29: 37.5 | N29: 37.5 | O29: 37.5 | P29: 37.5 | Q29: 37.5
B30: Blue | C30: 0.25 | D30: 0.25 | E30: 0.25 | F30: 0.25 | G30: 0.25 | H30: 0.25 | K30: Overall | L30: =44*37.5 -> 1650 | M30: =44*37.5 -> 1650 | N30: =44*37.5 -> 1650 | O30: =44*37.5 -> 1650 | P30: =44*37.5 -> 1650 | Q30: =44*37.5 -> 1650
B31: Red | C31: 0.25 | D31: 0.25 | E31: 0.25 | F31: 0.25 | G31: 0.25 | H31: 0.25
B32: Overall | C32: =SUM(C28:C31) -> 1 | D32: =SUM(D28:D31) -> 1 | E32: =SUM(E28:E31) -> 1 | F32: =SUM(F28:F31) -> 1 | G32: =SUM(G28:G31) -> 1 | H32: =SUM(H28:H31) -> 1

Sheet CALC | BLINE | HOURS
B2: Green Segment | K2: Amber Segment | T2: Workforce Group Standardised - Revised Horizon 2035 Matrix
C4: Workforce Group | L4: Workforce Group | U4: Skill Level
B5: Task | C5: A | D5: B | E5: C | F5: D | G5: E | H5: F | I5: Overall | K5: Task | L5: A | M5: B | N5: C | O5: D | P5: E | Q5: F | R5: Overall | T5: Task | U5: A | V5: B | W5: C | X5: D | Y5: E | Z5: F | AA5: Overall
B6: Prevention, Enablement and Rehabilitation | C6: =C$10*'INPUT | BLINE | TASKS'!C6 -> 0 | D6: =D$10*'INPUT | BLINE | TASKS'!D6 -> 1904732.9 | E6: =E$10*'INPUT | BLINE | TASKS'!E6 -> 586372.01 | F6: =F$10*'INPUT | BLINE | TASKS'!F6 -> 232316.46 | G6: =G$10*'INPUT | BLINE | TASKS'!G6 -> 95229.508 | H6: =H$10*'INPUT | BLINE | TASKS'!H6 -> 116191.83 | I6: =SUM(C6:H6) -> 2934842.7 | K6: Prevention, Enablement and Rehabilitation | L6: =L$10*'INPUT | BLINE | TASKS'!L6 -> 0 | M6: =M$10*'INPUT | BLINE | TASKS'!M6 -> 1904732.9 | N6: =N$10*'INPUT | BLINE | TASKS'!N6 -> 586372.01 | O6: =O$10*'INPUT | BLINE | TASKS'!O6 -> 232316.46 | P6: =P$10*'INPUT | BLINE | TASKS'!P6 -> 95229.508 | Q6: =Q$10*'INPUT | BLINE | TASKS'!Q6 -> 116191.83 | R6: =SUM(L6:Q6) -> 2934842.7 | T6: Prevention, Enablement and Rehabilitation | U6: =C6+L6+C16+L16 -> 0 | V6: =D6+M6+D16+M16 -> 7618931.8 | W6: =E6+N6+E16+N16 -> 2345488 | X6: =F6+O6+F16+O16 -> 929265.83 | Y6: =G6+P6+G16+P16 -> 380918.03 | Z6: =H6+Q6+H16+Q16 -> 464767.3 | AA6: =I6+R6+I16+R16 -> 11739371
B7: Assessment and Planning | C7: =C$10*'INPUT | BLINE | TASKS'!C7 -> 0 | D7: =D$10*'INPUT | BLINE | TASKS'!D7 -> 1223790.9 | E7: =E$10*'INPUT | BLINE | TASKS'!E7 -> 559327.59 | F7: =F$10*'INPUT | BLINE | TASKS'!F7 -> 191753.27 | G7: =G$10*'INPUT | BLINE | TASKS'!G7 -> 149278.69 | H7: =H$10*'INPUT | BLINE | TASKS'!H7 -> 160880.99 | I7: =SUM(C7:H7) -> 2285031.5 | K7: Assessment and Planning | L7: =L$10*'INPUT | BLINE | TASKS'!L7 -> 0 | M7: =M$10*'INPUT | BLINE | TASKS'!M7 -> 1223790.9 | N7: =N$10*'INPUT | BLINE | TASKS'!N7 -> 559327.59 | O7: =O$10*'INPUT | BLINE | TASKS'!O7 -> 191753.27 | P7: =P$10*'INPUT | BLINE | TASKS'!P7 -> 149278.69 | Q7: =Q$10*'INPUT | BLINE | TASKS'!Q7 -> 160880.99 | R7: =SUM(L7:Q7) -> 2285031.5 | T7: Assessment and Planning | U7: =C7+L7+C17+L17 -> 0 | V7: =D7+M7+D17+M17 -> 4895163.7 | W7: =E7+N7+E17+N17 -> 2237310.4 | X7: =F7+O7+F17+O17 -> 767013.07 | Y7: =G7+P7+G17+P17 -> 597114.75 | Z7: =H7+Q7+H17+Q17 -> 643523.96 | AA7: =I7+R7+I17+R17 -> 9140125.8
B8: Treatment and Relieving | C8: =C$10*'INPUT | BLINE | TASKS'!C8 -> 0 | D8: =D$10*'INPUT | BLINE | TASKS'!D8 -> 1119030.6 | E8: =E$10*'INPUT | BLINE | TASKS'!E8 -> 303634.98 | F8: =F$10*'INPUT | BLINE | TASKS'!F8 -> 105095.54 | G8: =G$10*'INPUT | BLINE | TASKS'!G8 -> 79786.885 | H8: =H$10*'INPUT | BLINE | TASKS'!H8 -> 80440.494 | I8: =SUM(C8:H8) -> 1687988.5 | K8: Treatment and Relieving | L8: =L$10*'INPUT | BLINE | TASKS'!L8 -> 0 | M8: =M$10*'INPUT | BLINE | TASKS'!M8 -> 1119030.6 | N8: =N$10*'INPUT | BLINE | TASKS'!N8 -> 303634.98 | O8: =O$10*'INPUT | BLINE | TASKS'!O8 -> 105095.54 | P8: =P$10*'INPUT | BLINE | TASKS'!P8 -> 79786.885 | Q8: =Q$10*'INPUT | BLINE | TASKS'!Q8 -> 80440.494 | R8: =SUM(L8:Q8) -> 1687988.5 | T8: Treatment and Relieving | U8: =C8+L8+C18+L18 -> 0 | V8: =D8+M8+D18+M18 -> 4476122.4 | W8: =E8+N8+E18+N18 -> 1214539.9 | X8: =F8+O8+F18+O18 -> 420382.16 | Y8: =G8+P8+G18+P18 -> 319147.54 | Z8: =H8+Q8+H18+Q18 -> 321761.98 | AA8: =I8+R8+I18+R18 -> 6751954
B9: Linking | C9: =C$10*'INPUT | BLINE | TASKS'!C9 -> 0 | D9: =D$10*'INPUT | BLINE | TASKS'!D9 -> 761893.18 | E9: =E$10*'INPUT | BLINE | TASKS'!E9 -> 319615.77 | F9: =F$10*'INPUT | BLINE | TASKS'!F9 -> 160408.98 | G9: =G$10*'INPUT | BLINE | TASKS'!G9 -> 84934.426 | H9: =H$10*'INPUT | BLINE | TASKS'!H9 -> 71502.662 | I9: =SUM(C9:H9) -> 1398355 | K9: Linking | L9: =L$10*'INPUT | BLINE | TASKS'!L9 -> 0 | M9: =M$10*'INPUT | BLINE | TASKS'!M9 -> 761893.18 | N9: =N$10*'INPUT | BLINE | TASKS'!N9 -> 319615.77 | O9: =O$10*'INPUT | BLINE | TASKS'!O9 -> 160408.98 | P9: =P$10*'INPUT | BLINE | TASKS'!P9 -> 84934.426 | Q9: =Q$10*'INPUT | BLINE | TASKS'!Q9 -> 71502.662 | R9: =SUM(L9:Q9) -> 1398355 | T9: Linking | U9: =C9+L9+C19+L19 -> 0 | V9: =D9+M9+D19+M19 -> 3047572.7 | W9: =E9+N9+E19+N19 -> 1278463.1 | X9: =F9+O9+F19+O19 -> 641635.93 | Y9: =G9+P9+G19+P19 -> 339737.71 | Z9: =H9+Q9+H19+Q19 -> 286010.65 | AA9: =I9+R9+I19+R19 -> 5593420.1
B10: Overall | C10: =C$28 -> 0 | D10: =D$28 -> 5009447.7 | E10: =E$28 -> 1768950.3 | F10: =F$28 -> 689574.25 | G10: =G$28 -> 409229.51 | H10: =H$28 -> 429015.97 | I10: =SUM(C10:H10) -> 8306217.7 | K10: Overall | L10: =C$29 -> 0 | M10: =D$29 -> 5009447.7 | N10: =E$29 -> 1768950.3 | O10: =F$29 -> 689574.25 | P10: =G$29 -> 409229.51 | Q10: =H$29 -> 429015.97 | R10: =SUM(L10:Q10) -> 8306217.7 | T10: Overall | U10: =C10+L10+C20+L20 -> 0 | V10: =D10+M10+D20+M20 -> 20037791 | W10: =E10+N10+E20+N20 -> 7075801.4 | X10: =F10+O10+F20+O20 -> 2758297 | Y10: =G10+P10+G20+P20 -> 1636918 | Z10: =H10+Q10+H20+Q20 -> 1716063.9 | AA10: =I10+R10+I20+R20 -> 33224871
B12: Blue Segment | K12: Red Segment
C14: Workforce Group | L14: Workforce Group
B15: Task | C15: A | D15: B | E15: C | F15: D | G15: E | H15: F | I15: Overall | K15: Task | L15: A | M15: B | N15: C | O15: D | P15: E | Q15: F | R15: Overall
B16: Prevention, Enablement and Rehabilitation | C16: =C$20*'INPUT | BLINE | TASKS'!C16 -> 0 | D16: =D$20*'INPUT | BLINE | TASKS'!D16 -> 1904732.9 | E16: =E$20*'INPUT | BLINE | TASKS'!E16 -> 586372.01 | F16: =F$20*'INPUT | BLINE | TASKS'!F16 -> 232316.46 | G16: =G$20*'INPUT | BLINE | TASKS'!G16 -> 95229.508 | H16: =H$20*'INPUT | BLINE | TASKS'!H16 -> 116191.83 | I16: =SUM(C16:H16) -> 2934842.7 | K16: Prevention, Enablement and Rehabilitation | L16: =L$20*'INPUT | BLINE | TASKS'!L16 -> 0 | M16: =M$20*'INPUT | BLINE | TASKS'!M16 -> 1904732.9 | N16: =N$20*'INPUT | BLINE | TASKS'!N16 -> 586372.01 | O16: =O$20*'INPUT | BLINE | TASKS'!O16 -> 232316.46 | P16: =P$20*'INPUT | BLINE | TASKS'!P16 -> 95229.508 | Q16: =Q$20*'INPUT | BLINE | TASKS'!Q16 -> 116191.83 | R16: =SUM(L16:Q16) -> 2934842.7
B17: Assessment and Planning | C17: =C$20*'INPUT | BLINE | TASKS'!C17 -> 0 | D17: =D$20*'INPUT | BLINE | TASKS'!D17 -> 1223790.9 | E17: =E$20*'INPUT | BLINE | TASKS'!E17 -> 559327.59 | F17: =F$20*'INPUT | BLINE | TASKS'!F17 -> 191753.27 | G17: =G$20*'INPUT | BLINE | TASKS'!G17 -> 149278.69 | H17: =H$20*'INPUT | BLINE | TASKS'!H17 -> 160880.99 | I17: =SUM(C17:H17) -> 2285031.5 | K17: Assessment and Planning | L17: =L$20*'INPUT | BLINE | TASKS'!L17 -> 0 | M17: =M$20*'INPUT | BLINE | TASKS'!M17 -> 1223790.9 | N17: =N$20*'INPUT | BLINE | TASKS'!N17 -> 559327.59 | O17: =O$20*'INPUT | BLINE | TASKS'!O17 -> 191753.27 | P17: =P$20*'INPUT | BLINE | TASKS'!P17 -> 149278.69 | Q17: =Q$20*'INPUT | BLINE | TASKS'!Q17 -> 160880.99 | R17: =SUM(L17:Q17) -> 2285031.5
B18: Treatment and Relieving | C18: =C$20*'INPUT | BLINE | TASKS'!C18 -> 0 | D18: =D$20*'INPUT | BLINE | TASKS'!D18 -> 1119030.6 | E18: =E$20*'INPUT | BLINE | TASKS'!E18 -> 303634.98 | F18: =F$20*'INPUT | BLINE | TASKS'!F18 -> 105095.54 | G18: =G$20*'INPUT | BLINE | TASKS'!G18 -> 79786.885 | H18: =H$20*'INPUT | BLINE | TASKS'!H18 -> 80440.494 | I18: =SUM(C18:H18) -> 1687988.5 | K18: Treatment and Relieving | L18: =L$20*'INPUT | BLINE | TASKS'!L18 -> 0 | M18: =M$20*'INPUT | BLINE | TASKS'!M18 -> 1119030.6 | N18: =N$20*'INPUT | BLINE | TASKS'!N18 -> 303634.98 | O18: =O$20*'INPUT | BLINE | TASKS'!O18 -> 105095.54 | P18: =P$20*'INPUT | BLINE | TASKS'!P18 -> 79786.885 | Q18: =Q$20*'INPUT | BLINE | TASKS'!Q18 -> 80440.494 | R18: =SUM(L18:Q18) -> 1687988.5
B19: Linking | C19: =C$20*'INPUT | BLINE | TASKS'!C19 -> 0 | D19: =D$20*'INPUT | BLINE | TASKS'!D19 -> 761893.18 | E19: =E$20*'INPUT | BLINE | TASKS'!E19 -> 319615.77 | F19: =F$20*'INPUT | BLINE | TASKS'!F19 -> 160408.98 | G19: =G$20*'INPUT | BLINE | TASKS'!G19 -> 84934.426 | H19: =H$20*'INPUT | BLINE | TASKS'!H19 -> 71502.662 | I19: =SUM(C19:H19) -> 1398355 | K19: Linking | L19: =L$20*'INPUT | BLINE | TASKS'!L19 -> 0 | M19: =M$20*'INPUT | BLINE | TASKS'!M19 -> 761893.18 | N19: =N$20*'INPUT | BLINE | TASKS'!N19 -> 319615.77 | O19: =O$20*'INPUT | BLINE | TASKS'!O19 -> 160408.98 | P19: =P$20*'INPUT | BLINE | TASKS'!P19 -> 84934.426 | Q19: =Q$20*'INPUT | BLINE | TASKS'!Q19 -> 71502.662 | R19: =SUM(L19:Q19) -> 1398355
B20: Overall | C20: =C$30 -> 0 | D20: =D$30 -> 5009447.7 | E20: =E$30 -> 1768950.3 | F20: =F$30 -> 689574.25 | G20: =G$30 -> 409229.51 | H20: =H$30 -> 429015.97 | I20: =SUM(C20:H20) -> 8306217.7 | K20: Overall | L20: =C$31 -> 0 | M20: =D$31 -> 5009447.7 | N20: =E$31 -> 1768950.3 | O20: =F$31 -> 689574.25 | P20: =G$31 -> 409229.51 | Q20: =H$31 -> 429015.97 | R20: =SUM(L20:Q20) -> 8306217.7
B24: Workforce Split by Group and Population Segment | K24: Workforce Hours per Year by Group
C26: Workforce Group | L26: Workforce Group
B27: Segment | C27: A | D27: B | E27: C | F27: D | G27: E | H27: F | K27: Segment | L27: A | M27: B | N27: C | O27: D | P27: E | Q27: F
B28: Green | C28: =L$32*'INPUT | BLINE | TASKS'!C28 -> 0 | D28: =M$32*'INPUT | BLINE | TASKS'!D28 -> 5009447.7 | E28: =N$32*'INPUT | BLINE | TASKS'!E28 -> 1768950.3 | F28: =O$32*'INPUT | BLINE | TASKS'!F28 -> 689574.25 | G28: =P$32*'INPUT | BLINE | TASKS'!G28 -> 409229.51 | H28: =Q$32*'INPUT | BLINE | TASKS'!H28 -> 429015.97 | K28: Weeks per FTE | L28: 44 | M28: 44 | N28: 44 | O28: 44 | P28: 44 | Q28: 44
B29: Amber | C29: =L$32*'INPUT | BLINE | TASKS'!C29 -> 0 | D29: =M$32*'INPUT | BLINE | TASKS'!D29 -> 5009447.7 | E29: =N$32*'INPUT | BLINE | TASKS'!E29 -> 1768950.3 | F29: =O$32*'INPUT | BLINE | TASKS'!F29 -> 689574.25 | G29: =P$32*'INPUT | BLINE | TASKS'!G29 -> 409229.51 | H29: =Q$32*'INPUT | BLINE | TASKS'!H29 -> 429015.97 | K29: Hours per Week | L29: 37.5 | M29: 37.5 | N29: 37.5 | O29: 37.5 | P29: 37.5 | Q29: 37.5
B30: Blue | C30: =L$32*'INPUT | BLINE | TASKS'!C30 -> 0 | D30: =M$32*'INPUT | BLINE | TASKS'!D30 -> 5009447.7 | E30: =N$32*'INPUT | BLINE | TASKS'!E30 -> 1768950.3 | F30: =O$32*'INPUT | BLINE | TASKS'!F30 -> 689574.25 | G30: =P$32*'INPUT | BLINE | TASKS'!G30 -> 409229.51 | H30: =Q$32*'INPUT | BLINE | TASKS'!H30 -> 429015.97 | K30: Hour per FTE | L30: =L28*L29 -> 1650 | M30: =M28*M29 -> 1650 | N30: =N28*N29 -> 1650 | O30: =O28*O29 -> 1650 | P30: =P28*P29 -> 1650 | Q30: =Q28*Q29 -> 1650
B31: Red | C31: =L$32*'INPUT | BLINE | TASKS'!C31 -> 0 | D31: =M$32*'INPUT | BLINE | TASKS'!D31 -> 5009447.7 | E31: =N$32*'INPUT | BLINE | TASKS'!E31 -> 1768950.3 | F31: =O$32*'INPUT | BLINE | TASKS'!F31 -> 689574.25 | G31: =P$32*'INPUT | BLINE | TASKS'!G31 -> 409229.51 | H31: =Q$32*'INPUT | BLINE | TASKS'!H31 -> 429015.97 | K31: FTE | L31: =SUMIF('INPUT | WORKFORCE'!$D:$D,'CALC | BLINE | HOURS'!L$27,'INPUT | WORKFORCE'!$E:$E) -> 0 | M31: =SUMIF('INPUT | WORKFORCE'!$D:$D,'CALC | BLINE | HOURS'!M$27,'INPUT | WORKFORCE'!$E:$E) -> 12144.116 | N31: =SUMIF('INPUT | WORKFORCE'!$D:$D,'CALC | BLINE | HOURS'!N$27,'INPUT | WORKFORCE'!$E:$E) -> 4288.3645 | O31: =SUMIF('INPUT | WORKFORCE'!$D:$D,'CALC | BLINE | HOURS'!O$27,'INPUT | WORKFORCE'!$E:$E) -> 1671.6951 | P31: =SUMIF('INPUT | WORKFORCE'!$D:$D,'CALC | BLINE | HOURS'!P$27,'INPUT | WORKFORCE'!$E:$E) -> 992.07154 | Q31: =SUMIF('INPUT | WORKFORCE'!$D:$D,'CALC | BLINE | HOURS'!Q$27,'INPUT | WORKFORCE'!$E:$E) -> 1040.0387
B32: Overall | C32: =SUM(C28:C31) -> 0 | D32: =SUM(D28:D31) -> 20037791 | E32: =SUM(E28:E31) -> 7075801.4 | F32: =SUM(F28:F31) -> 2758297 | G32: =SUM(G28:G31) -> 1636918 | H32: =SUM(H28:H31) -> 1716063.9 | K32: Overall | L32: =L30*L31 -> 0 | M32: =M30*M31 -> 20037791 | N32: =N30*N31 -> 7075801.4 | O32: =O30*O31 -> 2758297 | P32: =P30*P31 -> 1636918 | Q32: =Q30*Q31 -> 1716063.9

Sheet CALC | FCAST | HOURS
B2: Green Segment | K2: Amber Segment | T2: Workforce Group Standardised - Revised Horizon 2035 Matrix
C4: Workforce Group | L4: Workforce Group | U4: Skill Level
B5: Task | C5: A | D5: B | E5: C | F5: D | G5: E | H5: F | I5: Overall | K5: Task | L5: A | M5: B | N5: C | O5: D | P5: E | Q5: F | R5: Overall | T5: Task | U5: A | V5: B | W5: C | X5: D | Y5: E | Z5: F | AA5: Overall
B6: Prevention, Enablement and Rehabilitation | C6: =C$10*'INPUT | FCAST | TASKS'!C6 -> 0 | D6: =D$10*'INPUT | FCAST | TASKS'!D6 -> 1904732.9 | E6: =E$10*'INPUT | FCAST | TASKS'!E6 -> 586372.01 | F6: =F$10*'INPUT | FCAST | TASKS'!F6 -> 232316.46 | G6: =G$10*'INPUT | FCAST | TASKS'!G6 -> 95229.508 | H6: =H$10*'INPUT | FCAST | TASKS'!H6 -> 116191.83 | I6: =SUM(C6:H6) -> 2934842.7 | K6: Prevention, Enablement and Rehabilitation | L6: =L$10*'INPUT | FCAST | TASKS'!L6 -> 0 | M6: =M$10*'INPUT | FCAST | TASKS'!M6 -> 1904732.9 | N6: =N$10*'INPUT | FCAST | TASKS'!N6 -> 586372.01 | O6: =O$10*'INPUT | FCAST | TASKS'!O6 -> 232316.46 | P6: =P$10*'INPUT | FCAST | TASKS'!P6 -> 95229.508 | Q6: =Q$10*'INPUT | FCAST | TASKS'!Q6 -> 116191.83 | R6: =SUM(L6:Q6) -> 2934842.7 | T6: Prevention, Enablement and Rehabilitation | U6: =C6+L6+C16+L16 -> 0 | V6: =D6+M6+D16+M16 -> 7618931.8 | W6: =E6+N6+E16+N16 -> 2345488 | X6: =F6+O6+F16+O16 -> 929265.83 | Y6: =G6+P6+G16+P16 -> 380918.03 | Z6: =H6+Q6+H16+Q16 -> 464767.3 | AA6: =I6+R6+I16+R16 -> 11739371
B7: Assessment and Planning | C7: =C$10*'INPUT | FCAST | TASKS'!C7 -> 0 | D7: =D$10*'INPUT | FCAST | TASKS'!D7 -> 1223790.9 | E7: =E$10*'INPUT | FCAST | TASKS'!E7 -> 559327.59 | F7: =F$10*'INPUT | FCAST | TASKS'!F7 -> 191753.27 | G7: =G$10*'INPUT | FCAST | TASKS'!G7 -> 149278.69 | H7: =H$10*'INPUT | FCAST | TASKS'!H7 -> 160880.99 | I7: =SUM(C7:H7) -> 2285031.5 | K7: Assessment and Planning | L7: =L$10*'INPUT | FCAST | TASKS'!L7 -> 0 | M7: =M$10*'INPUT | FCAST | TASKS'!M7 -> 1223790.9 | N7: =N$10*'INPUT | FCAST | TASKS'!N7 -> 559327.59 | O7: =O$10*'INPUT | FCAST | TASKS'!O7 -> 191753.27 | P7: =P$10*'INPUT | FCAST | TASKS'!P7 -> 149278.69 | Q7: =Q$10*'INPUT | FCAST | TASKS'!Q7 -> 160880.99 | R7: =SUM(L7:Q7) -> 2285031.5 | T7: Assessment and Planning | U7: =C7+L7+C17+L17 -> 0 | V7: =D7+M7+D17+M17 -> 4895163.7 | W7: =E7+N7+E17+N17 -> 2237310.4 | X7: =F7+O7+F17+O17 -> 767013.07 | Y7: =G7+P7+G17+P17 -> 597114.75 | Z7: =H7+Q7+H17+Q17 -> 643523.96 | AA7: =I7+R7+I17+R17 -> 9140125.8
B8: Treatment and Relieving | C8: =C$10*'INPUT | FCAST | TASKS'!C8 -> 0 | D8: =D$10*'INPUT | FCAST | TASKS'!D8 -> 1119030.6 | E8: =E$10*'INPUT | FCAST | TASKS'!E8 -> 303634.98 | F8: =F$10*'INPUT | FCAST | TASKS'!F8 -> 105095.54 | G8: =G$10*'INPUT | FCAST | TASKS'!G8 -> 79786.885 | H8: =H$10*'INPUT | FCAST | TASKS'!H8 -> 80440.494 | I8: =SUM(C8:H8) -> 1687988.5 | K8: Treatment and Relieving | L8: =L$10*'INPUT | FCAST | TASKS'!L8 -> 0 | M8: =M$10*'INPUT | FCAST | TASKS'!M8 -> 1119030.6 | N8: =N$10*'INPUT | FCAST | TASKS'!N8 -> 303634.98 | O8: =O$10*'INPUT | FCAST | TASKS'!O8 -> 105095.54 | P8: =P$10*'INPUT | FCAST | TASKS'!P8 -> 79786.885 | Q8: =Q$10*'INPUT | FCAST | TASKS'!Q8 -> 80440.494 | R8: =SUM(L8:Q8) -> 1687988.5 | T8: Treatment and Relieving | U8: =C8+L8+C18+L18 -> 0 | V8: =D8+M8+D18+M18 -> 4476122.4 | W8: =E8+N8+E18+N18 -> 1214539.9 | X8: =F8+O8+F18+O18 -> 420382.16 | Y8: =G8+P8+G18+P18 -> 319147.54 | Z8: =H8+Q8+H18+Q18 -> 321761.98 | AA8: =I8+R8+I18+R18 -> 6751954
B9: Linking | C9: =C$10*'INPUT | FCAST | TASKS'!C9 -> 0 | D9: =D$10*'INPUT | FCAST | TASKS'!D9 -> 761893.18 | E9: =E$10*'INPUT | FCAST | TASKS'!E9 -> 319615.77 | F9: =F$10*'INPUT | FCAST | TASKS'!F9 -> 160408.98 | G9: =G$10*'INPUT | FCAST | TASKS'!G9 -> 84934.426 | H9: =H$10*'INPUT | FCAST | TASKS'!H9 -> 71502.662 | I9: =SUM(C9:H9) -> 1398355 | K9: Linking | L9: =L$10*'INPUT | FCAST | TASKS'!L9 -> 0 | M9: =M$10*'INPUT | FCAST | TASKS'!M9 -> 761893.18 | N9: =N$10*'INPUT | FCAST | TASKS'!N9 -> 319615.77 | O9: =O$10*'INPUT | FCAST | TASKS'!O9 -> 160408.98 | P9: =P$10*'INPUT | FCAST | TASKS'!P9 -> 84934.426 | Q9: =Q$10*'INPUT | FCAST | TASKS'!Q9 -> 71502.662 | R9: =SUM(L9:Q9) -> 1398355 | T9: Linking | U9: =C9+L9+C19+L19 -> 0 | V9: =D9+M9+D19+M19 -> 3047572.7 | W9: =E9+N9+E19+N19 -> 1278463.1 | X9: =F9+O9+F19+O19 -> 641635.93 | Y9: =G9+P9+G19+P19 -> 339737.71 | Z9: =H9+Q9+H19+Q19 -> 286010.65 | AA9: =I9+R9+I19+R19 -> 5593420.1
B10: Overall | C10: =C$28 -> 0 | D10: =D$28 -> 5009447.7 | E10: =E$28 -> 1768950.3 | F10: =F$28 -> 689574.25 | G10: =G$28 -> 409229.51 | H10: =H$28 -> 429015.97 | I10: =SUM(C10:H10) -> 8306217.7 | K10: Overall | L10: =C$29 -> 0 | M10: =D$29 -> 5009447.7 | N10: =E$29 -> 1768950.3 | O10: =F$29 -> 689574.25 | P10: =G$29 -> 409229.51 | Q10: =H$29 -> 429015.97 | R10: =SUM(L10:Q10) -> 8306217.7 | T10: Overall | U10: =C10+L10+C20+L20 -> 0 | V10: =D10+M10+D20+M20 -> 20037791 | W10: =E10+N10+E20+N20 -> 7075801.4 | X10: =F10+O10+F20+O20 -> 2758297 | Y10: =G10+P10+G20+P20 -> 1636918 | Z10: =H10+Q10+H20+Q20 -> 1716063.9 | AA10: =I10+R10+I20+R20 -> 33224871
B12: Blue Segment | K12: Red Segment
C14: Workforce Group | L14: Workforce Group
B15: Task | C15: A | D15: B | E15: C | F15: D | G15: E | H15: F | I15: Overall | K15: Task | L15: A | M15: B | N15: C | O15: D | P15: E | Q15: F | R15: Overall
B16: Prevention, Enablement and Rehabilitation | C16: =C$20*'INPUT | FCAST | TASKS'!C16 -> 0 | D16: =D$20*'INPUT | FCAST | TASKS'!D16 -> 1904732.9 | E16: =E$20*'INPUT | FCAST | TASKS'!E16 -> 586372.01 | F16: =F$20*'INPUT | FCAST | TASKS'!F16 -> 232316.46 | G16: =G$20*'INPUT | FCAST | TASKS'!G16 -> 95229.508 | H16: =H$20*'INPUT | FCAST | TASKS'!H16 -> 116191.83 | I16: =SUM(C16:H16) -> 2934842.7 | K16: Prevention, Enablement and Rehabilitation | L16: =L$20*'INPUT | FCAST | TASKS'!L16 -> 0 | M16: =M$20*'INPUT | FCAST | TASKS'!M16 -> 1904732.9 | N16: =N$20*'INPUT | FCAST | TASKS'!N16 -> 586372.01 | O16: =O$20*'INPUT | FCAST | TASKS'!O16 -> 232316.46 | P16: =P$20*'INPUT | FCAST | TASKS'!P16 -> 95229.508 | Q16: =Q$20*'INPUT | FCAST | TASKS'!Q16 -> 116191.83 | R16: =SUM(L16:Q16) -> 2934842.7
B17: Assessment and Planning | C17: =C$20*'INPUT | FCAST | TASKS'!C17 -> 0 | D17: =D$20*'INPUT | FCAST | TASKS'!D17 -> 1223790.9 | E17: =E$20*'INPUT | FCAST | TASKS'!E17 -> 559327.59 | F17: =F$20*'INPUT | FCAST | TASKS'!F17 -> 191753.27 | G17: =G$20*'INPUT | FCAST | TASKS'!G17 -> 149278.69 | H17: =H$20*'INPUT | FCAST | TASKS'!H17 -> 160880.99 | I17: =SUM(C17:H17) -> 2285031.5 | K17: Assessment and Planning | L17: =L$20*'INPUT | FCAST | TASKS'!L17 -> 0 | M17: =M$20*'INPUT | FCAST | TASKS'!M17 -> 1223790.9 | N17: =N$20*'INPUT | FCAST | TASKS'!N17 -> 559327.59 | O17: =O$20*'INPUT | FCAST | TASKS'!O17 -> 191753.27 | P17: =P$20*'INPUT | FCAST | TASKS'!P17 -> 149278.69 | Q17: =Q$20*'INPUT | FCAST | TASKS'!Q17 -> 160880.99 | R17: =SUM(L17:Q17) -> 2285031.5
B18: Treatment and Relieving | C18: =C$20*'INPUT | FCAST | TASKS'!C18 -> 0 | D18: =D$20*'INPUT | FCAST | TASKS'!D18 -> 1119030.6 | E18: =E$20*'INPUT | FCAST | TASKS'!E18 -> 303634.98 | F18: =F$20*'INPUT | FCAST | TASKS'!F18 -> 105095.54 | G18: =G$20*'INPUT | FCAST | TASKS'!G18 -> 79786.885 | H18: =H$20*'INPUT | FCAST | TASKS'!H18 -> 80440.494 | I18: =SUM(C18:H18) -> 1687988.5 | K18: Treatment and Relieving | L18: =L$20*'INPUT | FCAST | TASKS'!L18 -> 0 | M18: =M$20*'INPUT | FCAST | TASKS'!M18 -> 1119030.6 | N18: =N$20*'INPUT | FCAST | TASKS'!N18 -> 303634.98 | O18: =O$20*'INPUT | FCAST | TASKS'!O18 -> 105095.54 | P18: =P$20*'INPUT | FCAST | TASKS'!P18 -> 79786.885 | Q18: =Q$20*'INPUT | FCAST | TASKS'!Q18 -> 80440.494 | R18: =SUM(L18:Q18) -> 1687988.5
B19: Linking | C19: =C$20*'INPUT | FCAST | TASKS'!C19 -> 0 | D19: =D$20*'INPUT | FCAST | TASKS'!D19 -> 761893.18 | E19: =E$20*'INPUT | FCAST | TASKS'!E19 -> 319615.77 | F19: =F$20*'INPUT | FCAST | TASKS'!F19 -> 160408.98 | G19: =G$20*'INPUT | FCAST | TASKS'!G19 -> 84934.426 | H19: =H$20*'INPUT | FCAST | TASKS'!H19 -> 71502.662 | I19: =SUM(C19:H19) -> 1398355 | K19: Linking | L19: =L$20*'INPUT | FCAST | TASKS'!L19 -> 0 | M19: =M$20*'INPUT | FCAST | TASKS'!M19 -> 761893.18 | N19: =N$20*'INPUT | FCAST | TASKS'!N19 -> 319615.77 | O19: =O$20*'INPUT | FCAST | TASKS'!O19 -> 160408.98 | P19: =P$20*'INPUT | FCAST | TASKS'!P19 -> 84934.426 | Q19: =Q$20*'INPUT | FCAST | TASKS'!Q19 -> 71502.662 | R19: =SUM(L19:Q19) -> 1398355
B20: Overall | C20: =C$30 -> 0 | D20: =D$30 -> 5009447.7 | E20: =E$30 -> 1768950.3 | F20: =F$30 -> 689574.25 | G20: =G$30 -> 409229.51 | H20: =H$30 -> 429015.97 | I20: =SUM(C20:H20) -> 8306217.7 | K20: Overall | L20: =C$31 -> 0 | M20: =D$31 -> 5009447.7 | N20: =E$31 -> 1768950.3 | O20: =F$31 -> 689574.25 | P20: =G$31 -> 409229.51 | Q20: =H$31 -> 429015.97 | R20: =SUM(L20:Q20) -> 8306217.7
B24: Workforce Split by Group and Population Segment | K24: Workforce Hours per Year by Group
C26: Workforce Group | L26: Workforce Group
B27: Segment | C27: A | D27: B | E27: C | F27: D | G27: E | H27: F | K27: Segment | L27: A | M27: B | N27: C | O27: D | P27: E | Q27: F | R27: Overall
B28: Green | C28: =L$32*'INPUT | FCAST | TASKS'!C28 -> 0 | D28: =M$32*'INPUT | FCAST | TASKS'!D28 -> 5009447.7 | E28: =N$32*'INPUT | FCAST | TASKS'!E28 -> 1768950.3 | F28: =O$32*'INPUT | FCAST | TASKS'!F28 -> 689574.25 | G28: =P$32*'INPUT | FCAST | TASKS'!G28 -> 409229.51 | H28: =Q$32*'INPUT | FCAST | TASKS'!H28 -> 429015.97 | K28: Weeks per FTE | L28: 44 | M28: 44 | N28: 44 | O28: 44 | P28: 44 | Q28: 44 | R28: 44
B29: Amber | C29: =L$32*'INPUT | FCAST | TASKS'!C29 -> 0 | D29: =M$32*'INPUT | FCAST | TASKS'!D29 -> 5009447.7 | E29: =N$32*'INPUT | FCAST | TASKS'!E29 -> 1768950.3 | F29: =O$32*'INPUT | FCAST | TASKS'!F29 -> 689574.25 | G29: =P$32*'INPUT | FCAST | TASKS'!G29 -> 409229.51 | H29: =Q$32*'INPUT | FCAST | TASKS'!H29 -> 429015.97 | K29: Hours per Week | L29: 37.5 | M29: 37.5 | N29: 37.5 | O29: 37.5 | P29: 37.5 | Q29: 37.5 | R29: 37.5
B30: Blue | C30: =L$32*'INPUT | FCAST | TASKS'!C30 -> 0 | D30: =M$32*'INPUT | FCAST | TASKS'!D30 -> 5009447.7 | E30: =N$32*'INPUT | FCAST | TASKS'!E30 -> 1768950.3 | F30: =O$32*'INPUT | FCAST | TASKS'!F30 -> 689574.25 | G30: =P$32*'INPUT | FCAST | TASKS'!G30 -> 409229.51 | H30: =Q$32*'INPUT | FCAST | TASKS'!H30 -> 429015.97 | K30: Hour per FTE | L30: =L28*L29 -> 1650 | M30: =M28*M29 -> 1650 | N30: =N28*N29 -> 1650 | O30: =O28*O29 -> 1650 | P30: =P28*P29 -> 1650 | Q30: =Q28*Q29 -> 1650 | R30: =R28*R29 -> 1650
B31: Red | C31: =L$32*'INPUT | FCAST | TASKS'!C31 -> 0 | D31: =M$32*'INPUT | FCAST | TASKS'!D31 -> 5009447.7 | E31: =N$32*'INPUT | FCAST | TASKS'!E31 -> 1768950.3 | F31: =O$32*'INPUT | FCAST | TASKS'!F31 -> 689574.25 | G31: =P$32*'INPUT | FCAST | TASKS'!G31 -> 409229.51 | H31: =Q$32*'INPUT | FCAST | TASKS'!H31 -> 429015.97 | K31: FTE | L31: =SUMIF('INPUT | WORKFORCE'!$D:$D,'CALC | FCAST | HOURS'!L$27,'INPUT | WORKFORCE'!$E:$E) -> 0 | M31: =SUMIF('INPUT | WORKFORCE'!$D:$D,'CALC | FCAST | HOURS'!M$27,'INPUT | WORKFORCE'!$E:$E) -> 12144.116 | N31: =SUMIF('INPUT | WORKFORCE'!$D:$D,'CALC | FCAST | HOURS'!N$27,'INPUT | WORKFORCE'!$E:$E) -> 4288.3645 | O31: =SUMIF('INPUT | WORKFORCE'!$D:$D,'CALC | FCAST | HOURS'!O$27,'INPUT | WORKFORCE'!$E:$E) -> 1671.6951 | P31: =SUMIF('INPUT | WORKFORCE'!$D:$D,'CALC | FCAST | HOURS'!P$27,'INPUT | WORKFORCE'!$E:$E) -> 992.07154 | Q31: =SUMIF('INPUT | WORKFORCE'!$D:$D,'CALC | FCAST | HOURS'!Q$27,'INPUT | WORKFORCE'!$E:$E) -> 1040.0387 | R31: =SUM(L31:Q31) -> 20136.285
B32: Overall | C32: =SUM(C28:C31) -> 0 | D32: =SUM(D28:D31) -> 20037791 | E32: =SUM(E28:E31) -> 7075801.4 | F32: =SUM(F28:F31) -> 2758297 | G32: =SUM(G28:G31) -> 1636918 | H32: =SUM(H28:H31) -> 1716063.9 | K32: Overall | L32: =L30*L31 -> 0 | M32: =M30*M31 -> 20037791 | N32: =N30*N31 -> 7075801.4 | O32: =O30*O31 -> 2758297 | P32: =P30*P31 -> 1636918 | Q32: =Q30*Q31 -> 1716063.9 | R32: =SUM(L32:Q32) -> 33224871

Sheet OUTPUT | BLINE | HR PER PT
B2: Green Segment | K2: Amber Segment
C4: Workforce Group | L4: Workforce Group
B5: Task | C5: A | D5: B | E5: C | F5: D | G5: E | H5: F | I5: Overall | K5: Task | L5: A | M5: B | N5: C | O5: D | P5: E | Q5: F | R5: Overall
B6: Prevention, Enablement and Rehabilitation | C6: ='CALC | BLINE | HOURS'!C6/'INPUT | SEGMENTATION'!$E$8 -> 0 | D6: ='CALC | BLINE | HOURS'!D6/'INPUT | SEGMENTATION'!$E$8 -> 6.8773598 | E6: ='CALC | BLINE | HOURS'!E6/'INPUT | SEGMENTATION'!$E$8 -> 2.1171951 | F6: ='CALC | BLINE | HOURS'!F6/'INPUT | SEGMENTATION'!$E$8 -> 0.83881779 | G6: ='CALC | BLINE | HOURS'!G6/'INPUT | SEGMENTATION'!$E$8 -> 0.34384221 | H6: ='CALC | BLINE | HOURS'!H6/'INPUT | SEGMENTATION'!$E$8 -> 0.4195302 | I6: ='CALC | BLINE | HOURS'!I6/'INPUT | SEGMENTATION'!$E$8 -> 10.596745 | K6: Prevention, Enablement and Rehabilitation | L6: ='CALC | BLINE | HOURS'!L6/'INPUT | SEGMENTATION'!$E$9 -> 0 | M6: ='CALC | BLINE | HOURS'!M6/'INPUT | SEGMENTATION'!$E$9 -> 6.3126229 | N6: ='CALC | BLINE | HOURS'!N6/'INPUT | SEGMENTATION'!$E$9 -> 1.9433408 | O6: ='CALC | BLINE | HOURS'!O6/'INPUT | SEGMENTATION'!$E$9 -> 0.76993795 | P6: ='CALC | BLINE | HOURS'!P6/'INPUT | SEGMENTATION'!$E$9 -> 0.31560748 | Q6: ='CALC | BLINE | HOURS'!Q6/'INPUT | SEGMENTATION'!$E$9 -> 0.38508032 | R6: ='CALC | BLINE | HOURS'!R6/'INPUT | SEGMENTATION'!$E$9 -> 9.7265895
B7: Assessment and Planning | C7: ='CALC | BLINE | HOURS'!C7/'INPUT | SEGMENTATION'!$E$8 -> 0 | D7: ='CALC | BLINE | HOURS'!D7/'INPUT | SEGMENTATION'!$E$8 -> 4.4187037 | E7: ='CALC | BLINE | HOURS'!E7/'INPUT | SEGMENTATION'!$E$8 -> 2.0195467 | F7: ='CALC | BLINE | HOURS'!F7/'INPUT | SEGMENTATION'!$E$8 -> 0.69235754 | G7: ='CALC | BLINE | HOURS'!G7/'INPUT | SEGMENTATION'!$E$8 -> 0.5389959 | H7: ='CALC | BLINE | HOURS'!H7/'INPUT | SEGMENTATION'!$E$8 -> 0.58088797 | I7: ='CALC | BLINE | HOURS'!I7/'INPUT | SEGMENTATION'!$E$8 -> 8.2504918 | K7: Assessment and Planning | L7: ='CALC | BLINE | HOURS'!L7/'INPUT | SEGMENTATION'!$E$9 -> 0 | M7: ='CALC | BLINE | HOURS'!M7/'INPUT | SEGMENTATION'!$E$9 -> 4.0558602 | N7: ='CALC | BLINE | HOURS'!N7/'INPUT | SEGMENTATION'!$E$9 -> 1.8537109 | O7: ='CALC | BLINE | HOURS'!O7/'INPUT | SEGMENTATION'!$E$9 -> 0.63550434 | P7: ='CALC | BLINE | HOURS'!P7/'INPUT | SEGMENTATION'!$E$9 -> 0.49473605 | Q7: ='CALC | BLINE | HOURS'!Q7/'INPUT | SEGMENTATION'!$E$9 -> 0.53318814 | R7: ='CALC | BLINE | HOURS'!R7/'INPUT | SEGMENTATION'!$E$9 -> 7.5729996
B8: Treatment and Relieving | C8: ='CALC | BLINE | HOURS'!C8/'INPUT | SEGMENTATION'!$E$8 -> 0 | D8: ='CALC | BLINE | HOURS'!D8/'INPUT | SEGMENTATION'!$E$8 -> 4.0404489 | E8: ='CALC | BLINE | HOURS'!E8/'INPUT | SEGMENTATION'!$E$8 -> 1.0963253 | F8: ='CALC | BLINE | HOURS'!F8/'INPUT | SEGMENTATION'!$E$8 -> 0.37946519 | G8: ='CALC | BLINE | HOURS'!G8/'INPUT | SEGMENTATION'!$E$8 -> 0.28808402 | H8: ='CALC | BLINE | HOURS'!H8/'INPUT | SEGMENTATION'!$E$8 -> 0.29044398 | I8: ='CALC | BLINE | HOURS'!I8/'INPUT | SEGMENTATION'!$E$8 -> 6.0947674 | K8: Treatment and Relieving | L8: ='CALC | BLINE | HOURS'!L8/'INPUT | SEGMENTATION'!$E$9 -> 0 | M8: ='CALC | BLINE | HOURS'!M8/'INPUT | SEGMENTATION'!$E$9 -> 3.7086659 | N8: ='CALC | BLINE | HOURS'!N8/'INPUT | SEGMENTATION'!$E$9 -> 1.0063002 | O8: ='CALC | BLINE | HOURS'!O8/'INPUT | SEGMENTATION'!$E$9 -> 0.34830526 | P8: ='CALC | BLINE | HOURS'!P8/'INPUT | SEGMENTATION'!$E$9 -> 0.26442789 | Q8: ='CALC | BLINE | HOURS'!Q8/'INPUT | SEGMENTATION'!$E$9 -> 0.26659407 | R8: ='CALC | BLINE | HOURS'!R8/'INPUT | SEGMENTATION'!$E$9 -> 5.5942933
B9: Linking | C9: ='CALC | BLINE | HOURS'!C9/'INPUT | SEGMENTATION'!$E$8 -> 0 | D9: ='CALC | BLINE | HOURS'!D9/'INPUT | SEGMENTATION'!$E$8 -> 2.7509439 | E9: ='CALC | BLINE | HOURS'!E9/'INPUT | SEGMENTATION'!$E$8 -> 1.1540267 | F9: ='CALC | BLINE | HOURS'!F9/'INPUT | SEGMENTATION'!$E$8 -> 0.57918371 | G9: ='CALC | BLINE | HOURS'!G9/'INPUT | SEGMENTATION'!$E$8 -> 0.30667008 | H9: ='CALC | BLINE | HOURS'!H9/'INPUT | SEGMENTATION'!$E$8 -> 0.25817243 | I9: ='CALC | BLINE | HOURS'!I9/'INPUT | SEGMENTATION'!$E$8 -> 5.0489968 | K9: Linking | L9: ='CALC | BLINE | HOURS'!L9/'INPUT | SEGMENTATION'!$E$9 -> 0 | M9: ='CALC | BLINE | HOURS'!M9/'INPUT | SEGMENTATION'!$E$9 -> 2.5250491 | N9: ='CALC | BLINE | HOURS'!N9/'INPUT | SEGMENTATION'!$E$9 -> 1.0592634 | O9: ='CALC | BLINE | HOURS'!O9/'INPUT | SEGMENTATION'!$E$9 -> 0.53162382 | P9: ='CALC | BLINE | HOURS'!P9/'INPUT | SEGMENTATION'!$E$9 -> 0.28148776 | Q9: ='CALC | BLINE | HOURS'!Q9/'INPUT | SEGMENTATION'!$E$9 -> 0.2369725 | R9: ='CALC | BLINE | HOURS'!R9/'INPUT | SEGMENTATION'!$E$9 -> 4.6343966
B10: Overall | C10: ='CALC | BLINE | HOURS'!C10/'INPUT | SEGMENTATION'!$E$8 -> 0 | D10: ='CALC | BLINE | HOURS'!D10/'INPUT | SEGMENTATION'!$E$8 -> 18.087456 | E10: ='CALC | BLINE | HOURS'!E10/'INPUT | SEGMENTATION'!$E$8 -> 6.3870938 | F10: ='CALC | BLINE | HOURS'!F10/'INPUT | SEGMENTATION'!$E$8 -> 2.4898242 | G10: ='CALC | BLINE | HOURS'!G10/'INPUT | SEGMENTATION'!$E$8 -> 1.4775922 | H10: ='CALC | BLINE | HOURS'!H10/'INPUT | SEGMENTATION'!$E$8 -> 1.5490346 | I10: ='CALC | BLINE | HOURS'!I10/'INPUT | SEGMENTATION'!$E$8 -> 29.991001 | K10: Overall | L10: ='CALC | BLINE | HOURS'!L10/'INPUT | SEGMENTATION'!$E$9 -> 0 | M10: ='CALC | BLINE | HOURS'!M10/'INPUT | SEGMENTATION'!$E$9 -> 16.602198 | N10: ='CALC | BLINE | HOURS'!N10/'INPUT | SEGMENTATION'!$E$9 -> 5.8626152 | O10: ='CALC | BLINE | HOURS'!O10/'INPUT | SEGMENTATION'!$E$9 -> 2.2853714 | P10: ='CALC | BLINE | HOURS'!P10/'INPUT | SEGMENTATION'!$E$9 -> 1.3562592 | Q10: ='CALC | BLINE | HOURS'!Q10/'INPUT | SEGMENTATION'!$E$9 -> 1.421835 | R10: ='CALC | BLINE | HOURS'!R10/'INPUT | SEGMENTATION'!$E$9 -> 27.528279
B12: Blue Segment | K12: Red Segment
C14: Workforce Group | L14: Workforce Group
B15: Task | C15: A | D15: B | E15: C | F15: D | G15: E | H15: F | I15: Overall | K15: Task | L15: A | M15: B | N15: C | O15: D | P15: E | Q15: F | R15: Overall
B16: Prevention, Enablement and Rehabilitation | C16: ='CALC | BLINE | HOURS'!C16/'INPUT | SEGMENTATION'!$E$10 -> 0 | D16: ='CALC | BLINE | HOURS'!D16/'INPUT | SEGMENTATION'!$E$10 -> 84.023687 | E16: ='CALC | BLINE | HOURS'!E16/'INPUT | SEGMENTATION'!$E$10 -> 25.86669 | F16: ='CALC | BLINE | HOURS'!F16/'INPUT | SEGMENTATION'!$E$10 -> 10.248201 | G16: ='CALC | BLINE | HOURS'!G16/'INPUT | SEGMENTATION'!$E$10 -> 4.2008694 | H16: ='CALC | BLINE | HOURS'!H16/'INPUT | SEGMENTATION'!$E$10 -> 5.1255823 | I16: ='CALC | BLINE | HOURS'!I16/'INPUT | SEGMENTATION'!$E$10 -> 129.46503 | K16: Prevention, Enablement and Rehabilitation | L16: ='CALC | BLINE | HOURS'!L16/'INPUT | SEGMENTATION'!$E$11 -> 0 | M16: ='CALC | BLINE | HOURS'!M16/'INPUT | SEGMENTATION'!$E$11 -> 392.72844 | N16: ='CALC | BLINE | HOURS'!N16/'INPUT | SEGMENTATION'!$E$11 -> 120.90144 | O16: ='CALC | BLINE | HOURS'!O16/'INPUT | SEGMENTATION'!$E$11 -> 47.900301 | P16: ='CALC | BLINE | HOURS'!P16/'INPUT | SEGMENTATION'!$E$11 -> 19.63495 | Q16: ='CALC | BLINE | HOURS'!Q16/'INPUT | SEGMENTATION'!$E$11 -> 23.957077 | R16: ='CALC | BLINE | HOURS'!R16/'INPUT | SEGMENTATION'!$E$11 -> 605.12222
B17: Assessment and Planning | C17: ='CALC | BLINE | HOURS'!C17/'INPUT | SEGMENTATION'!$E$10 -> 0 | D17: ='CALC | BLINE | HOURS'!D17/'INPUT | SEGMENTATION'!$E$10 -> 53.985219 | E17: ='CALC | BLINE | HOURS'!E17/'INPUT | SEGMENTATION'!$E$10 -> 24.673677 | F17: ='CALC | BLINE | HOURS'!F17/'INPUT | SEGMENTATION'!$E$10 -> 8.4588322 | G17: ='CALC | BLINE | HOURS'!G17/'INPUT | SEGMENTATION'!$E$10 -> 6.5851466 | H17: ='CALC | BLINE | HOURS'!H17/'INPUT | SEGMENTATION'!$E$10 -> 7.0969601 | I17: ='CALC | BLINE | HOURS'!I17/'INPUT | SEGMENTATION'!$E$10 -> 100.79983 | K17: Assessment and Planning | L17: ='CALC | BLINE | HOURS'!L17/'INPUT | SEGMENTATION'!$E$11 -> 0 | M17: ='CALC | BLINE | HOURS'!M17/'INPUT | SEGMENTATION'!$E$11 -> 252.32802 | N17: ='CALC | BLINE | HOURS'!N17/'INPUT | SEGMENTATION'!$E$11 -> 115.32528 | O17: ='CALC | BLINE | HOURS'!O17/'INPUT | SEGMENTATION'!$E$11 -> 39.536756 | P17: ='CALC | BLINE | HOURS'!P17/'INPUT | SEGMENTATION'!$E$11 -> 30.779111 | Q17: ='CALC | BLINE | HOURS'!Q17/'INPUT | SEGMENTATION'!$E$11 -> 33.171338 | R17: ='CALC | BLINE | HOURS'!R17/'INPUT | SEGMENTATION'!$E$11 -> 471.14051
B18: Treatment and Relieving | C18: ='CALC | BLINE | HOURS'!C18/'INPUT | SEGMENTATION'!$E$10 -> 0 | D18: ='CALC | BLINE | HOURS'!D18/'INPUT | SEGMENTATION'!$E$10 -> 49.363916 | E18: ='CALC | BLINE | HOURS'!E18/'INPUT | SEGMENTATION'!$E$10 -> 13.394282 | F18: ='CALC | BLINE | HOURS'!F18/'INPUT | SEGMENTATION'!$E$10 -> 4.6360907 | G18: ='CALC | BLINE | HOURS'!G18/'INPUT | SEGMENTATION'!$E$10 -> 3.5196473 | H18: ='CALC | BLINE | HOURS'!H18/'INPUT | SEGMENTATION'!$E$10 -> 3.5484801 | I18: ='CALC | BLINE | HOURS'!I18/'INPUT | SEGMENTATION'!$E$10 -> 74.462416 | K18: Treatment and Relieving | L18: ='CALC | BLINE | HOURS'!L18/'INPUT | SEGMENTATION'!$E$11 -> 0 | M18: ='CALC | BLINE | HOURS'!M18/'INPUT | SEGMENTATION'!$E$11 -> 230.72796 | N18: ='CALC | BLINE | HOURS'!N18/'INPUT | SEGMENTATION'!$E$11 -> 62.60515 | O18: ='CALC | BLINE | HOURS'!O18/'INPUT | SEGMENTATION'!$E$11 -> 21.669184 | P18: ='CALC | BLINE | HOURS'!P18/'INPUT | SEGMENTATION'!$E$11 -> 16.450904 | Q18: ='CALC | BLINE | HOURS'!Q18/'INPUT | SEGMENTATION'!$E$11 -> 16.585669 | R18: ='CALC | BLINE | HOURS'!R18/'INPUT | SEGMENTATION'!$E$11 -> 348.03887
B19: Linking | C19: ='CALC | BLINE | HOURS'!C19/'INPUT | SEGMENTATION'!$E$10 -> 0 | D19: ='CALC | BLINE | HOURS'!D19/'INPUT | SEGMENTATION'!$E$10 -> 33.609475 | E19: ='CALC | BLINE | HOURS'!E19/'INPUT | SEGMENTATION'!$E$10 -> 14.099244 | F19: ='CALC | BLINE | HOURS'!F19/'INPUT | SEGMENTATION'!$E$10 -> 7.0761385 | G19: ='CALC | BLINE | HOURS'!G19/'INPUT | SEGMENTATION'!$E$10 -> 3.7467214 | H19: ='CALC | BLINE | HOURS'!H19/'INPUT | SEGMENTATION'!$E$10 -> 3.1542045 | I19: ='CALC | BLINE | HOURS'!I19/'INPUT | SEGMENTATION'!$E$10 -> 61.685783 | K19: Linking | L19: ='CALC | BLINE | HOURS'!L19/'INPUT | SEGMENTATION'!$E$11 -> 0 | M19: ='CALC | BLINE | HOURS'!M19/'INPUT | SEGMENTATION'!$E$11 -> 157.09138 | N19: ='CALC | BLINE | HOURS'!N19/'INPUT | SEGMENTATION'!$E$11 -> 65.900158 | O19: ='CALC | BLINE | HOURS'!O19/'INPUT | SEGMENTATION'!$E$11 -> 33.074017 | P19: ='CALC | BLINE | HOURS'!P19/'INPUT | SEGMENTATION'!$E$11 -> 17.512253 | Q19: ='CALC | BLINE | HOURS'!Q19/'INPUT | SEGMENTATION'!$E$11 -> 14.742817 | R19: ='CALC | BLINE | HOURS'!R19/'INPUT | SEGMENTATION'!$E$11 -> 288.32062
B20: Overall | C20: ='CALC | BLINE | HOURS'!C20/'INPUT | SEGMENTATION'!$E$10 -> 0 | D20: ='CALC | BLINE | HOURS'!D20/'INPUT | SEGMENTATION'!$E$10 -> 220.9823 | E20: ='CALC | BLINE | HOURS'!E20/'INPUT | SEGMENTATION'!$E$10 -> 78.033894 | F20: ='CALC | BLINE | HOURS'!F20/'INPUT | SEGMENTATION'!$E$10 -> 30.419262 | G20: ='CALC | BLINE | HOURS'!G20/'INPUT | SEGMENTATION'!$E$10 -> 18.052385 | H20: ='CALC | BLINE | HOURS'!H20/'INPUT | SEGMENTATION'!$E$10 -> 18.925227 | I20: ='CALC | BLINE | HOURS'!I20/'INPUT | SEGMENTATION'!$E$10 -> 366.41306 | K20: Overall | L20: ='CALC | BLINE | HOURS'!L20/'INPUT | SEGMENTATION'!$E$11 -> 0 | M20: ='CALC | BLINE | HOURS'!M20/'INPUT | SEGMENTATION'!$E$11 -> 1032.8758 | N20: ='CALC | BLINE | HOURS'!N20/'INPUT | SEGMENTATION'!$E$11 -> 364.73203 | O20: ='CALC | BLINE | HOURS'!O20/'INPUT | SEGMENTATION'!$E$11 -> 142.18026 | P20: ='CALC | BLINE | HOURS'!P20/'INPUT | SEGMENTATION'!$E$11 -> 84.377218 | Q20: ='CALC | BLINE | HOURS'!Q20/'INPUT | SEGMENTATION'!$E$11 -> 88.456901 | R20: ='CALC | BLINE | HOURS'!R20/'INPUT | SEGMENTATION'!$E$11 -> 1712.6222

Sheet OUTPUT | FCAST | HR PER PT
B2: Green Segment | K2: Amber Segment
C4: Workforce Group | L4: Workforce Group
B5: Task | C5: A | D5: B | E5: C | F5: D | G5: E | H5: F | I5: Overall | K5: Task | L5: A | M5: B | N5: C | O5: D | P5: E | Q5: F | R5: Overall
B6: Prevention, Enablement and Rehabilitation | C6: ='CALC | FCAST | HOURS'!C6/'INPUT | SEGMENTATION'!$F$8 -> 0 | D6: ='CALC | FCAST | HOURS'!D6/'INPUT | SEGMENTATION'!$F$8 -> 6.7206023 | E6: ='CALC | FCAST | HOURS'!E6/'INPUT | SEGMENTATION'!$F$8 -> 2.0689373 | F6: ='CALC | FCAST | HOURS'!F6/'INPUT | SEGMENTATION'!$F$8 -> 0.81969839 | G6: ='CALC | FCAST | HOURS'!G6/'INPUT | SEGMENTATION'!$F$8 -> 0.33600493 | H6: ='CALC | FCAST | HOURS'!H6/'INPUT | SEGMENTATION'!$F$8 -> 0.40996773 | I6: ='CALC | FCAST | HOURS'!I6/'INPUT | SEGMENTATION'!$F$8 -> 10.355211 | K6: Prevention, Enablement and Rehabilitation | L6: ='CALC | FCAST | HOURS'!L6/'INPUT | SEGMENTATION'!$F$9 -> 0 | M6: ='CALC | FCAST | HOURS'!M6/'INPUT | SEGMENTATION'!$F$9 -> 5.5047858 | N6: ='CALC | FCAST | HOURS'!N6/'INPUT | SEGMENTATION'!$F$9 -> 1.6946482 | O6: ='CALC | FCAST | HOURS'!O6/'INPUT | SEGMENTATION'!$F$9 -> 0.67140768 | P6: ='CALC | FCAST | HOURS'!P6/'INPUT | SEGMENTATION'!$F$9 -> 0.27521866 | Q6: ='CALC | FCAST | HOURS'!Q6/'INPUT | SEGMENTATION'!$F$9 -> 0.33580094 | R6: ='CALC | FCAST | HOURS'!R6/'INPUT | SEGMENTATION'!$F$9 -> 8.4818613
B7: Assessment and Planning | C7: ='CALC | FCAST | HOURS'!C7/'INPUT | SEGMENTATION'!$F$8 -> 0 | D7: ='CALC | FCAST | HOURS'!D7/'INPUT | SEGMENTATION'!$F$8 -> 4.317987 | E7: ='CALC | FCAST | HOURS'!E7/'INPUT | SEGMENTATION'!$F$8 -> 1.9735146 | F7: ='CALC | FCAST | HOURS'!F7/'INPUT | SEGMENTATION'!$F$8 -> 0.67657645 | G7: ='CALC | FCAST | HOURS'!G7/'INPUT | SEGMENTATION'!$F$8 -> 0.52671043 | H7: ='CALC | FCAST | HOURS'!H7/'INPUT | SEGMENTATION'!$F$8 -> 0.56764763 | I7: ='CALC | FCAST | HOURS'!I7/'INPUT | SEGMENTATION'!$F$8 -> 8.0624361 | K7: Assessment and Planning | L7: ='CALC | FCAST | HOURS'!L7/'INPUT | SEGMENTATION'!$F$9 -> 0 | M7: ='CALC | FCAST | HOURS'!M7/'INPUT | SEGMENTATION'!$F$9 -> 3.5368249 | N7: ='CALC | FCAST | HOURS'!N7/'INPUT | SEGMENTATION'!$F$9 -> 1.6164883 | O7: ='CALC | FCAST | HOURS'!O7/'INPUT | SEGMENTATION'!$F$9 -> 0.55417777 | P7: ='CALC | FCAST | HOURS'!P7/'INPUT | SEGMENTATION'!$F$9 -> 0.43142384 | Q7: ='CALC | FCAST | HOURS'!Q7/'INPUT | SEGMENTATION'!$F$9 -> 0.46495514 | R7: ='CALC | FCAST | HOURS'!R7/'INPUT | SEGMENTATION'!$F$9 -> 6.60387
B8: Treatment and Relieving | C8: ='CALC | FCAST | HOURS'!C8/'INPUT | SEGMENTATION'!$F$8 -> 0 | D8: ='CALC | FCAST | HOURS'!D8/'INPUT | SEGMENTATION'!$F$8 -> 3.9483539 | E8: ='CALC | FCAST | HOURS'!E8/'INPUT | SEGMENTATION'!$F$8 -> 1.0713365 | F8: ='CALC | FCAST | HOURS'!F8/'INPUT | SEGMENTATION'!$F$8 -> 0.37081594 | G8: ='CALC | FCAST | HOURS'!G8/'INPUT | SEGMENTATION'!$F$8 -> 0.28151764 | H8: ='CALC | FCAST | HOURS'!H8/'INPUT | SEGMENTATION'!$F$8 -> 0.28382382 | I8: ='CALC | FCAST | HOURS'!I8/'INPUT | SEGMENTATION'!$F$8 -> 5.9558478 | K8: Treatment and Relieving | L8: ='CALC | FCAST | HOURS'!L8/'INPUT | SEGMENTATION'!$F$9 -> 0 | M8: ='CALC | FCAST | HOURS'!M8/'INPUT | SEGMENTATION'!$F$9 -> 3.2340617 | N8: ='CALC | FCAST | HOURS'!N8/'INPUT | SEGMENTATION'!$F$9 -> 0.87752224 | O8: ='CALC | FCAST | HOURS'!O8/'INPUT | SEGMENTATION'!$F$9 -> 0.30373205 | P8: ='CALC | FCAST | HOURS'!P8/'INPUT | SEGMENTATION'!$F$9 -> 0.2305886 | Q8: ='CALC | FCAST | HOURS'!Q8/'INPUT | SEGMENTATION'!$F$9 -> 0.23247757 | R8: ='CALC | FCAST | HOURS'!R8/'INPUT | SEGMENTATION'!$F$9 -> 4.8783821
